Workbook

Sheet Dashboard
A1: DASHBOARD AKUNTANSI RAABIHA
A2: ="RAABIHA CLOTHING & KONVEKSI — Periode: " & TEXT(Dashboard!G5,"dd/mm/yyyy") & " s/d " & TEXT(Dashboard!H5,"dd/mm/yyyy") -> RAABIHA CLOTHING & KONVEKSI — Periode: 01/08/2026 s/d 31/08/2026
A4: TOTAL PENJUALAN (GROSS) | B4: DISKON & BIAYA MARKETPLACE | C4: NET REVENUE | D4: TOTAL BEBAN OPERASIONAL | E4: LABA BERSIH | F4: PAJAK TERHUTANG | G4: TANGGAL MULAI | H4: TANGGAL SELESAI
A5: =SUMIFS('INPUT Penjualan'!H4:H1000, 'INPUT Penjualan'!A4:A1000, ">="&$G$5, 'INPUT Penjualan'!A4:A1000, "<="&$H$5) -> 34000000 | B5: =SUMIFS('INPUT Penjualan'!I4:I1000, 'INPUT Penjualan'!A4:A1000, ">="&$G$5, 'INPUT Penjualan'!A4:A1000, "<="&$H$5) + SUMIFS('INPUT Penjualan'!J4:J1000, 'INPUT Penjualan'!A4:A1000, ">="&$G$5, 'INPUT Penjualan'!A4:A1000, "<="&$H$5) -> 3330000 | C5: =SUMIFS('INPUT Penjualan'!K4:K1000, 'INPUT Penjualan'!A4:A1000, ">="&$G$5, 'INPUT Penjualan'!A4:A1000, "<="&$H$5) -> 30670000 | D5: =SUMIFS('INPUT Beban & Kas Keluar'!F4:F997, 'INPUT Beban & Kas Keluar'!A4:A997, ">="&$G$5, 'INPUT Beban & Kas Keluar'!A4:A997, "<="&$H$5) -> 11150000 | E5: =VLOOKUP("LABA BERSIH (NET PROFIT)", 'Laba Rugi'!A:H, 8, FALSE) -> 8640000 | F5: ='Kalkulator Pajak'!D16 -> 0 | G5: 46235 | H5: 46265
A7: RINGKASAN PENJUALAN PER CHANNEL
A8: Channel | B8: Gross Sales | C8: Diskon | D8: Biaya Platform | E8: Net Sales | F8: % dari Total
A9: POS Toko | B9: =SUMIFS('INPUT Penjualan'!H4:H1000, 'INPUT Penjualan'!C4:C1000, A9, 'INPUT Penjualan'!A4:A1000, ">="&$G$5, 'INPUT Penjualan'!A4:A1000, "<="&$H$5) -> 7000000 | C9: =SUMIFS('INPUT Penjualan'!I4:I1000, 'INPUT Penjualan'!C4:C1000, A9, 'INPUT Penjualan'!A4:A1000, ">="&$G$5, 'INPUT Penjualan'!A4:A1000, "<="&$H$5) -> 0 | D9: =SUMIFS('INPUT Penjualan'!J4:J1000, 'INPUT Penjualan'!C4:C1000, A9, 'INPUT Penjualan'!A4:A1000, ">="&$G$5, 'INPUT Penjualan'!A4:A1000, "<="&$H$5) -> 10000 | E9: =SUMIFS('INPUT Penjualan'!K4:K1000, 'INPUT Penjualan'!C4:C1000, A9, 'INPUT Penjualan'!A4:A1000, ">="&$G$5, 'INPUT Penjualan'!A4:A1000, "<="&$H$5) -> 6990000 | F9: =IF(E$15=0, 0, E9/E$15) -> 0.2928362
A10: Web Raabiha | B10: =SUMIFS('INPUT Penjualan'!H5:H1001, 'INPUT Penjualan'!C5:C1001, A10, 'INPUT Penjualan'!A5:A1001, ">="&$G$5, 'INPUT Penjualan'!A5:A1001, "<="&$H$5) -> 3000000 | C10: =SUMIFS('INPUT Penjualan'!I5:I1001, 'INPUT Penjualan'!C5:C1001, A10, 'INPUT Penjualan'!A5:A1001, ">="&$G$5, 'INPUT Penjualan'!A5:A1001, "<="&$H$5) -> 0 | D10: =SUMIFS('INPUT Penjualan'!J5:J1001, 'INPUT Penjualan'!C5:C1001, A10, 'INPUT Penjualan'!A5:A1001, ">="&$G$5, 'INPUT Penjualan'!A5:A1001, "<="&$H$5) -> 20000 | E10: =SUMIFS('INPUT Penjualan'!K5:K1001, 'INPUT Penjualan'!C5:C1001, A10, 'INPUT Penjualan'!A5:A1001, ">="&$G$5, 'INPUT Penjualan'!A5:A1001, "<="&$H$5) -> 2980000 | F10: =IF(E$15=0, 0, E10/E$15) -> 0.1248429
A11: Shopee | B11: =SUMIFS('INPUT Penjualan'!H6:H1002, 'INPUT Penjualan'!C6:C1002, A11, 'INPUT Penjualan'!A6:A1002, ">="&$G$5, 'INPUT Penjualan'!A6:A1002, "<="&$H$5) -> 10000000 | C11: =SUMIFS('INPUT Penjualan'!I6:I1002, 'INPUT Penjualan'!C6:C1002, A11, 'INPUT Penjualan'!A6:A1002, ">="&$G$5, 'INPUT Penjualan'!A6:A1002, "<="&$H$5) -> 0 | D11: =SUMIFS('INPUT Penjualan'!J6:J1002, 'INPUT Penjualan'!C6:C1002, A11, 'INPUT Penjualan'!A6:A1002, ">="&$G$5, 'INPUT Penjualan'!A6:A1002, "<="&$H$5) -> 1500000 | E11: =SUMIFS('INPUT Penjualan'!K6:K1002, 'INPUT Penjualan'!C6:C1002, A11, 'INPUT Penjualan'!A6:A1002, ">="&$G$5, 'INPUT Penjualan'!A6:A1002, "<="&$H$5) -> 8500000 | F11: =IF(E$15=0, 0, E11/E$15) -> 0.35609552
A12: Lazada | B12: =SUMIFS('INPUT Penjualan'!H7:H1003, 'INPUT Penjualan'!C7:C1003, A12, 'INPUT Penjualan'!A7:A1003, ">="&$G$5, 'INPUT Penjualan'!A7:A1003, "<="&$H$5) -> 2000000 | C12: =SUMIFS('INPUT Penjualan'!I7:I1003, 'INPUT Penjualan'!C7:C1003, A12, 'INPUT Penjualan'!A7:A1003, ">="&$G$5, 'INPUT Penjualan'!A7:A1003, "<="&$H$5) -> 0 | D12: =SUMIFS('INPUT Penjualan'!J7:J1003, 'INPUT Penjualan'!C7:C1003, A12, 'INPUT Penjualan'!A7:A1003, ">="&$G$5, 'INPUT Penjualan'!A7:A1003, "<="&$H$5) -> 200000 | E12: =SUMIFS('INPUT Penjualan'!K7:K1003, 'INPUT Penjualan'!C7:C1003, A12, 'INPUT Penjualan'!A7:A1003, ">="&$G$5, 'INPUT Penjualan'!A7:A1003, "<="&$H$5) -> 1800000 | F12: =IF(E$15=0, 0, E12/E$15) -> 0.075408463
A13: Tokopedia | B13: =SUMIFS('INPUT Penjualan'!H8:H1004, 'INPUT Penjualan'!C8:C1004, A13, 'INPUT Penjualan'!A8:A1004, ">="&$G$5, 'INPUT Penjualan'!A8:A1004, "<="&$H$5) -> 4000000 | C13: =SUMIFS('INPUT Penjualan'!I8:I1004, 'INPUT Penjualan'!C8:C1004, A13, 'INPUT Penjualan'!A8:A1004, ">="&$G$5, 'INPUT Penjualan'!A8:A1004, "<="&$H$5) -> 0 | D13: =SUMIFS('INPUT Penjualan'!J8:J1004, 'INPUT Penjualan'!C8:C1004, A13, 'INPUT Penjualan'!A8:A1004, ">="&$G$5, 'INPUT Penjualan'!A8:A1004, "<="&$H$5) -> 400000 | E13: =SUMIFS('INPUT Penjualan'!K8:K1004, 'INPUT Penjualan'!C8:C1004, A13, 'INPUT Penjualan'!A8:A1004, ">="&$G$5, 'INPUT Penjualan'!A8:A1004, "<="&$H$5) -> 3600000 | F13: =IF(E$15=0, 0, E13/E$15) -> 0.15081692
A14: TikTok Shop | B14: =SUMIFS('INPUT Penjualan'!H9:H1005, 'INPUT Penjualan'!C9:C1005, A14, 'INPUT Penjualan'!A9:A1005, ">="&$G$5, 'INPUT Penjualan'!A9:A1005, "<="&$H$5) -> 0 | C14: =SUMIFS('INPUT Penjualan'!I9:I1005, 'INPUT Penjualan'!C9:C1005, A14, 'INPUT Penjualan'!A9:A1005, ">="&$G$5, 'INPUT Penjualan'!A9:A1005, "<="&$H$5) -> 0 | D14: =SUMIFS('INPUT Penjualan'!J9:J1005, 'INPUT Penjualan'!C9:C1005, A14, 'INPUT Penjualan'!A9:A1005, ">="&$G$5, 'INPUT Penjualan'!A9:A1005, "<="&$H$5) -> 0 | E14: =SUMIFS('INPUT Penjualan'!K9:K1005, 'INPUT Penjualan'!C9:C1005, A14, 'INPUT Penjualan'!A9:A1005, ">="&$G$5, 'INPUT Penjualan'!A9:A1005, "<="&$H$5) -> 0 | F14: =IF(E$15=0, 0, E14/E$15) -> 0
A15: TOTAL | B15: =SUM(B9:B14) -> 26000000 | C15: =SUM(C9:C14) -> 0 | D15: =SUM(D9:D14) -> 2130000 | E15: =SUM(E9:E14) -> 23870000
A17: MENU NAVIGASI CEPAT
A18: >> INPUT: Penjualan | C18: >> INPUT: Pembelian & Produksi | E18: >> INPUT: Beban & Kas Keluar | G18: >> INPUT: Jurnal Penyesuaian
A19: >> Laba Rugi | C19: >> Posisi Keuangan | E19: >> Arus Kas | G19: >> Kalkulator Pajak

Sheet _INSPEKSI_JSON
A1: SALIN TEKS DI SEL A2 (DAN A3 JIKA ADA) UNTUK DIANALISIS:
A2: { "time": "2026-08-14T03:23:37.319Z", "saldoAwalCOA": [ { "kode": "1-102", "nama": "Kas Bank BCA", "saldoAwal": "115.089.124" } ], "penjualan": [ { "tgl": "13/08/2026", "ref": "POS-20260101", "channel": "POS Toko", "kasAcc": "1-101", "jualAcc": "4-101", "gross": "", "diskon": "0", "biaya": "0", "net": "" }, { "tgl": "13/08/2026", "ref": "WEB-20260101", "channel": "Web Raabiha", "kasAcc": "1-205", "jualAcc": "4-102", "gross": "1.000.000", "diskon": "0", "biaya": "150.000", "net": "850.000" }, { "tgl": "07/08/2026", "ref": "SPE-JUN-W1", "channel": "Shopee", "kasAcc": "1-201", "jualAcc": "4-103", "gross": "", "diskon": "", "biaya": "0", "net": "" }, { "tgl": "07/08/2026", "ref": "LZD-JUN-W1", "channel": "Lazada", "kasAcc": "1-202", "jualAcc": "4-104", "gross": "", "diskon": "", "biaya": "0", "net": "" }, { "tgl": "07/08/2026", "ref": "TKP-JUN-W1", "channel": "Tokopedia", "kasAcc": "1-203", "jualAcc": "4-105", "gross": "", "diskon": "", "biaya": "0", "net": "" }, { "tgl": "07/08/2026", "ref": "TTK-JUN-W1", "channel": "TikTok Shop", "kasAcc": "1-204", "jualAcc": "4-106", "gross": "", "diskon": "", "biaya": "0", "net": "" }, { "tgl": "01/08/2026", "ref": "SPE-01082026", "channel": "Shopee", "kasAcc": "1-201", "jualAcc": "4-103", "gross": "9.692.205", "diskon": "", "biaya": "1.453.831", "net": "8.238.374" }, { "tgl": "01/08/2026", "ref": "TTK-01082026", "channel": "TikTok Shop", "kasAcc": "1-204", "jualAcc": "4-106", "gross": "4942060", "diskon": "", "biaya": "741.309", "net": "4.200.751" }, { "tgl": "02/08/2026", "ref": "SPE-02082026", "channel": "Shopee", "kasAcc": "1-201", "jualAcc": "4-103", "gross": "11.421.525", "diskon": "", "biaya": "1.713.229", "net": "9.708.296" }, { "tgl": "02/08/2026", "ref": "TTK-02082026", "channel": "TikTok Shop", "kasAcc": "1-204", "jualAcc": "4-106", "gross": "3.816.104", "diskon": "", "biaya": "572.416", "net": "3.243.688" }, { "tgl": "03/08/2026", "ref": "SPE-03082026", "channel": "Shopee", "kasAcc": "1-201", "jualAcc": "4-103", "gross": "11.678.090", "diskon": "", "biaya": "1.751.714", "net": "9.926.377" }, { "tgl": "03/08/2026", "ref": "TTK-03082026", "channel": "TikTok Shop", "kasAcc": "1-204", "jualAcc": "4-106", "gross": "6.840.788", "diskon": "", "biaya": "1.026.118", "net": "5.814.670" }, { "tgl": "04/08/2026", "ref": "SPE-04082026", "channel": "Shopee", "kasAcc": "1-201", "jualAcc": "4-103", "gross": "15.213.475", "diskon": "", "biaya": "2.282.021", "net": "12.931.454" }, { "tgl": "04/08/2026", "ref": "TTK-04082026", "channel": "TikTok Shop", "kasAcc": "1-204", "jualAcc": "4-106", "gross": "11.569.865", "diskon": "", "biaya": "1.735.480", "net": "9.834.385" }, { "tgl": "05/08/2026", "ref": "SPE-05082026", "channel": "Shopee", "kasAcc": "1-201", "jualAcc": "4-103", "gross": "12.284.514", "diskon": "", "biaya": "1.842.677", "net": "10.441.837" }, { "tgl": "05/08/2026", "ref": "TTK-05082026", "channel": "TikTok Shop", "kasAcc": "1-204", "jualAcc": "4-106", "gross": "10.988.197", "diskon": "", "biaya": "1.648.230", "net": "9.339.967" }, { "tgl": "06/08/2026", "ref": "SPE-06082026", "channel": "Shopee", "kasAcc": "1-201", "jualAcc": "4-103", "gross": "12.241.579", "diskon": "", "biaya": "1.836.237", "net": "10.405.342" }, { "tgl": "06/08/2026", "ref": "TTK-06082026", "channel": "TikTok Shop", "kasAcc": "1-204", "jualAcc": "4-106", "gross": "9.354.001", "diskon": "", "biaya": "1.403.100", "net": "7.950.901" }, { "tgl": "01/08/2026", "ref": "POS-01082026", "channel": "POS Toko", "kasAcc": "1-101", "jualAcc": "4-101", "gross": "812.000", "diskon": "", "biaya": "121.800", "net": "690.200" }, { "tgl": "02/08/2026", "ref": "POS-02082026", "channel": "POS Toko", "kasAcc": "1-101", "jualAcc": "4-101", "gross": "390.000", "diskon": "", "biaya": "58.500", "net": "331.500" }, { "tgl": "03/08/2026", "ref": "POS-03082026", "channel": "POS Toko", "kasAcc": "1-101", "jualAcc": "4-101", "gross": "350.000", "diskon": "", "biaya": "52.500", "net": "297.500" }, { "tgl": "04/08/2026", "ref": "POS-04082026", "channel": "POS Toko", "kasAcc": "1-101", "jualAcc": "4-101", "gross": "350.000", "diskon": "", "biaya": "52.500", "net": "297.500" }, { "tgl": "06/08/2026", "ref": "POS-06082026", "channel": "POS Toko", "kasAcc": "1-101", "jualAcc": "4-101", "gross": "485.000", "diskon": "", "biaya": "72.750", "net": "412.250" }, { "tgl": "07/08/2026", "ref": "SPE-07082026", "channel": "Shopee", "kasAcc": "1-201", "jualAcc": "4-103", "gross": "9.814.236", "diskon": "", "biaya": "1.472.135", "net": "8.342.101" }, { "tgl": "07/08/2026", "ref": "TTK-07082026", "channel": "TikTok Shop", "kasAcc": "1-204", "jualAcc": "4-106", "gross": "5.915.740", "diskon": "", "biaya": "887.361", "net": "5.028.379" }, { "tgl": "08/08/2026", "ref": "SPE-08082026", "channel": "Shopee", "kasAcc": "1-201", "jualAcc": "4-103", "gross": "26.011.864", "diskon": "", "biaya": "3.901.780", "net": "22.110.084" }, { "tgl": "08/08/2026", "ref": "TTK-08082026", "channel": "TikTok Shop", "kasAcc": "1-204", "jualAcc": "4-106", "gross": "8.757.979", "diskon": "", "biaya": "1.313.697", "net": "7.444.282" }, { "tgl": "09/08/2026", "ref": "SPE-09082026", "channel": "Shopee", "kasAcc": "1-201", "jualAcc": "4-103", "gross": "13.672.412", "diskon": "", "biaya": "2.050.862", "net": "11.621.550" }, { "tgl": "09/08/2026", "ref": "TTK-09082026", "channel": "TikTok Shop", "kasAcc": "1-204", "jualAcc": "4-106", "gross": "5.492.036", "diskon": "", "biaya": "823.805", "net": "4.668.231" }, { "tgl": "10/08/2026", "ref": "SPE-10082026", "channel": "Shopee", "kasAcc": "1-201", "jualAcc": "4-103", "gross": "14.179.629", "diskon": "", "biaya": "2.126.944", "net": "12.052.685" }, { "tgl": "10/08/2026", "ref": "TTK-10082026", "channel": "TikTok Shop", "kasAcc": "1-204", "jualAcc": "4-106", "gross": "6.160.265", "diskon": "", "biaya": "924.040", "net": "5.236.225" }, { "tgl": "11/08/2026", "ref": "POS-110820261", "channel": "POS Toko", "kasAcc": "1-102", "jualAcc": "4-101", "gross": "185.000", "diskon": "", "biaya": "27.750", "net": "157.250" }, { "tgl": "12/08/2026", "ref": "POS-120820261", "channel": "POS Toko", "kasAcc": "1-102", "jualAcc": "4-101", "gross": "35.000", "diskon": "", "biaya": "5.250", "net": "29.750" }, { "tgl": "08/08/2026", "ref": "POS-080820261", "channel": "POS Toko", "kasAcc": "1-102", "jualAcc": "4-101", "gross": "165.000", "diskon": "", "biaya": "24.750", "net": "140.250" }, { "tgl": "09/08/2026", "ref": "POS-090820261", "channel": "POS Toko", "kasAcc": "1-102", "jualAcc": "4-101", "gross": "170.000", "diskon": "", "biaya": "25.500", "net": "144.500" }, { "tgl": "11/08/2026", "ref": "SPE-11082026", "channel": "Shopee", "kasAcc": "1-201", "jualAcc": "4-103", "gross": "13.775.079", "diskon": "", "biaya": "2.066.262", "net": "11.708.817" }, { "tgl": "12/08/2026", "ref": "SPE-12082026", "channel": "Shopee", "kasAcc": "1-201", "jualAcc": "4-103", "gross": "12.334.535", "diskon": "", "biaya": "1.850.180", "net": "10.484.355" }, { "tgl": "11/08/2026", "ref": "TTK-11082026", "channel": "TikTok Shop", "kasAcc": "1-204", "jualAcc": "4-106", "gross": "9.787.001", "diskon": "", "biaya": "1.468.050", "net": "8.318.951" }, { "tgl": "12/08/2026", "ref": "TTK-12082026", "channel": "TikTok Shop", "kasAcc": "1-204", "jualAcc": "4-106", "gross": "9.130.504", "diskon": "", "biaya": "1.369.576", "net": "7.760.928" }, { "tgl": "07/08/2026", "ref": "POS-07082026", "channel": "POS Toko", "kasAcc": "1-101", "jualAcc": "4-101", "gross": "625.000", "diskon": "", "biaya": "93.750", "net": "531.250" }, { "tgl": "08/08/2026", "ref": "POS-08082026", "channel": "POS Toko", "kasAcc": "1-101", "jualAcc": "4-101", "gross": "630.000", "diskon": "", "biaya": "94.500", "net": "535.500" }, { "tgl": "09/08/2026", "ref": "POS-09082026", "channel": "POS Toko", "kasAcc": "1-101", "jualAcc": "4-101", "gross": "870.000", "diskon": "", "biaya": "130.500", "net": "739.500" }, { "tgl": "10/08/2026", "ref": "POS-10082026", "channel": "POS Toko", "kasAcc": "1-101", "jualAcc": "4-101", "gross": "280.000", "diskon": "", "biaya": "42.000", "net": "238.000" }, { "tgl": "11/08/2026", "ref": "POS-11082026", "channel": "POS Toko", "kasAcc": "1-101", "jualAcc": "4-101", "gross": "645.000", "diskon": "", "biaya": "96.750", "net": "548.250" }, { "tgl": "12/08/2026", "ref": "POS-12082026", "channel": "POS Toko", "kasAcc": "1-101", "jualAcc": "4-101", "gross": "1.030.000", "diskon": "", "biaya": "154.500", "net": "875.500" }, { "tgl": "RINGKASAN PER CHANNEL", "ref": "", "channel": "", "kasAcc": "", "jualAcc": "", "gross": "", "diskon": "", "biaya": "", "net": "" }, { "tgl": "POS Toko", "ref": "", "channel": "", "kasAcc": "", "jualAcc": "", "gross": "7.022.000", "diskon": "0", "biaya": "1.053.300", "net": "5.968.700" }, { "tgl": "Web Raabiha", "ref": "", "channel": "", "kasAcc": "", "jualAcc": "", "gross": "1.000.000", "diskon": "0", "biaya": "150.000", "net": "850.000" }, { "tgl": "Shopee", "ref": "", "channel": "", "kasAcc": "", "jualAcc": "", "gross": "162.319.143", "diskon": "0", "biaya": "24.347.871", "net": "137.971.272" }, { "tgl": "Lazada", "ref": "", "channel": "", "kasAcc": "", "jualAcc": "", "gross": "0", "diskon": "0", "biaya": "0", "net": "0" }, { "tgl": "Tokopedia", "ref": "", "channel": "", "kasAcc": "", "jualAcc": "", "gross": "0", "diskon": "0", "biaya": "0", "net": "0" }, { "tgl": "TikTok Shop", "ref": "", "channel": "", "kasAcc": "", "jualAcc": "", "gross": "92.754.540", "diskon": "0", "biaya": "13.913.181", "net": "78.841.359" } ], "pembelian": [ { "tgl": "01/08/2026", "faktur": "BP010826", "jenis": "Ongkos Jahit", "item": "Biaya produksi", "total": "11.555.600", "debAcc": "5-202", "kreAcc": "1-102" }, { "tgl": "01/08/2026", "faktur": "BB0108261", "jenis": "Bahan Baku", "item": "pembelian kain ity", "total": "14.300.000", "debAcc": "5-201", "kreAcc": "1-102" }, { "tgl": "07/08/2026", "faktur": "BB070826", "jenis": "Bahan Baku", "item": "pembelian kain jersey livina", "total": "5.096.250", "debAcc": "5-201", "kreAcc": "1-102" }, { "tgl": "08/08/2026", "faktur": "BB080826", "jenis": "Bahan Baku", "item": "pembelian kain ity", "total": "26.812.500", "debAcc": "5-201", "kreAcc": "1-102" }, { "tgl": "08/08/2026", "faktur": "BB0808261", "jenis": "Bahan Baku", "item": "pembelian kain ity", "total": "17.875.000", "debAcc": "5-201", "kreAcc": "1-102" }, { "tgl": "07/08/2026", "faktur": "BP070826", "jenis": "Ongkos Jahit", "item": "Biaya produksi", "total": "13.897.150", "debAcc": "5-202", "kreAcc": "1-102" }, { "tgl": "03/08/2026", "faktur": "AK030826", "jenis": "Aksesoris", "item": "logo bross", "total": "7.250.000", "debAcc": "5-203", "kreAcc": "1-102" } ], "beban": [ { "tgl": "01/08/2026", "bukti": "PC010826", "bebAcc": "6-109", "nama": "Beban Lain-lain", "detail": "pengisian kas kecil produksi", "nominal": "1.238.000", "sumber": "Kas Bank BCA" }, { "tgl": "01/08/2026", "bukti": "PR010826", "bebAcc": "3-102", "nama": "Prive Pemilik", "detail": "laba teh dini bulan juli", "nominal": "5.063.500", "sumber": "Kas Bank BCA" }, { "tgl": "01/08/2026", "bukti": "PR0108261", "bebAcc": "3-102", "nama": "Prive Pemilik", "detail": "tabungan", "nominal": "20.000.000", "sumber": "Kas Bank BCA" }, { "tgl": "01/08/2026", "bukti": "IT010826", "bebAcc": "6-104", "nama": "Beban Pemasaran & Iklan Digital", "detail": "iklan tiktok", "nominal": "1.776.000", "sumber": "Kas Bank BCA" }, { "tgl": "03/08/2026", "bukti": "BI030826", "bebAcc": "6-103", "nama": "Beban Listrik; Air & Internet", "detail": "wifi", "nominal": "340.440", "sumber": "Kas Bank BCA" }, { "tgl": "04/08/2026", "bukti": "BA040826", "bebAcc": "6-107", "nama": "Beban Administrasi & Bank", "detail": "biaya adm", "nominal": "30.000", "sumber": "Kas Bank BCA" }, { "tgl": "05/08/2026", "bukti": "BJ050826", "bebAcc": "6-109", "nama": "Beban Lain-lain", "detail": "konsultan shopee", "nominal": "3.799.000", "sumber": "Kas Bank BCA" }, { "tgl": "05/08/2026", "bukti": "BA050826", "bebAcc": "6-107", "nama": "Beban Administrasi & Bank", "detail": "biaya transfer bank", "nominal": "2.500", "sumber": "Kas Bank BCA" }, { "tgl": "05/08/2026", "bukti": "BJ0508261", "bebAcc": "6-109", "nama": "Beban Lain-lain", "detail": "konsultan accounting", "nominal": "3.333.400", "sumber": "Kas Bank BCA" }, { "tgl": "10/08/2026", "bukti": "PRT100826", "bebAcc": "1-401", "nama": "Peralatan & Mesin Jahit", "detail": "pembelian meja kantor", "nominal": "400.000", "sumber": "Kas Bank BCA" }, { "tgl": "10/08/2026", "bukti": "PRT1008261", "bebAcc": "1-401", "nama": "Peralatan & Mesin Jahit", "detail": "pembelian kursi", "nominal": "550.000", "sumber": "Kas Bank BCA" }, { "tgl": "10/08/2026", "bukti": "PRT1008262", "bebAcc": "1-401", "nama": "Peralatan & Mesin Jahit", "detail": "pembelian kursi", "nominal": "380.000", "sumber": "Kas Bank BCA" }, { "tgl": "07/08/2026", "bukti": "IKL070826", "bebAcc": "6-104", "nama": "Beban Pemasaran & Iklan Digital", "detail": "iklan tiktok", "nominal": "1.776.000", "sumber": "Kas Bank BCA" }, { "tgl": "07/08/2026", "bukti": "PJK070826", "bebAcc": "6-109", "nama": "Beban Lain-lain", "detail": "pajak mobil luxio", "nominal": "3.750.000", "sumber": "Kas Bank BCA" }, { "tgl": "07/08/2026", "bukti": "ADM070826", "bebAcc": "6-107", "nama": "Beban Administrasi & Bank", "detail": "admin tf", "nominal": "2.500", "sumber": "Kas Bank BCA" }, { "tgl": "11/08/2026", "bukti": "IKL110826", "bebAcc": "6-104", "nama": "Beban Pemasaran & Iklan Digital", "detail": "iklan tiktok", "nominal": "1.776.000", "sumber": "Kas Bank BCA" }, { "tgl": "11/08/2026", "bukti": "RF110826", "bebAcc": "4-103", "nama": "Penjualan — Shopee", "detail": "refund", "nominal": "55.000", "sumber": "Kas Bank BCA" }, { "tgl": "11/08/2026", "bukti": "ADM110826", "bebAcc": "6-107", "nama": "Beban Administrasi & Bank", "detail": "admin tf", "nominal": "2.500", "sumber": "Kas Bank BCA" }, { "tgl": "01/08/2026", "bukti": "WEB-IT01", "bebAcc": "6-110", "nama": "Beban IT, Server & Operational Web", "detail": "Sewa Domain & Server Web Raabiha", "nominal": "4.000.000", "sumber": "Kas Bank BCA" }, { "tgl": "05/08/2026", "bukti": "WEB-IT02", "bebAcc": "6-110", "nama": "Beban IT, Server & Operational Web", "detail": "Topup Saldo API Ongkir Biteship", "nominal": "100.000", "sumber": "Kas Bank BCA" }, { "tgl": "10/08/2026", "bukti": "WEB-IT03", "bebAcc": "6-110", "nama": "Beban IT, Server & Operational Web", "detail": "Topup Saldo API Email Resend Notifikasi", "nominal": "150.000", "sumber": "Kas Bank BCA" }, { "tgl": "01/08/2026", "bukti": "WEB-IT01", "bebAcc": "6-110", "nama": "Beban IT, Server & Operational Web", "detail": "Sewa Domain & Server Vercel Pro Web Raabiha", "nominal": "350.000", "sumber": "Kas Bank BCA" }, { "tgl": "05/08/2026", "bukti": "WEB-IT02", "bebAcc": "6-110", "nama": "Beban IT, Server & Operational Web", "detail": "Topup Saldo API Ongkir Biteship", "nominal": "100.000", "sumber": "Kas Bank BCA" }, { "tgl": "10/08/2026", "bukti": "WEB-IT03", "bebAcc": "6-110", "nama": "Beban IT, Server & Operational Web", "detail": "Topup Saldo API Email Resend Notifikasi", "nominal": "150.000", "sumber": "Kas Bank BCA" }, { "tgl": "RINGKASAN TOTAL BEBAN PER AKUN (OTOMATIS)", "bukti": "", "bebAcc": "", "nama": "", "detail": "", "nominal": "", "sumber": "" }, { "tgl": "6-101", "bukti": "Beban Gaji", "bebAcc": "", "nama": "", "detail": "", "nominal": "0", "sumber": "" }, { "tgl": "6-102", "bukti": "Beban Sewa", "bebAcc": "", "nama": "", "detail": "", "nominal": "0", "sumber": "" }, { "tgl": "6-103", "bukti": "Beban Listrik", "bebAcc": "", "nama": "", "detail": "", "nominal": "340.440", "sumber": "" }, { "tgl": "6-104", "bukti": "Beban Pemasaran", "bebAcc": "", "nama": "", "detail": "", "nominal": "5.328.000", "sumber": "" }, { "tgl": "6-105", "bukti": "Beban Kurir", "bebAcc": "", "nama": "", "detail": "", "nominal": "0", "sumber": "" }, { "tgl": "6-106", "bukti": "Beban Penyusutan", "bebAcc": "", "nama": "", "detail": "", "nominal": "0", "sumber": "" }, { "tgl": "6-107", "bukti": "Beban Admin & Bank", "bebAcc": "", "nama": "", "detail": "", "nominal": "37.500", "sumber": "" }, { "tgl": "6-108", "bukti": "Beban Perlengkapan", "bebAcc": "", "nama": "", "detail": "", "nominal": "0", "sumber": "" }, { "tgl": "6-109", "bukti": "Beban Lain-lain", "bebAcc": "", "nama": "", "detail": "", "nominal": "12.120.400", "sumber": "" }, { "tgl": "TOTAL SEMUA BEBAN", "bukti": "", "bebAcc": "", "nama": "", "detail": "", "nominal": "17.826.340", "sumber": "" } ], "penyesuaian": [ { "tgl": "29/07/2026", "ajp": "AJP-001", "detail": "Penyusutan mesin jahit bulan ini", "debAcc": "6-106", "kreAcc": "1-402", "nominal": "500.000" }, { "tgl": "07/08/2026", "ajp": "", "detail": "penarikan saldo tiktok", "debAcc": "1-102", "kreAcc": "1-204", "nominal": "29.854.839" }, { "tgl": "07/08/2026", "ajp": "", "detail": "penarikan saldo shopee", "debAcc": "1-102", "kreAcc": "1-201", "nominal": "47.511.384" }, { "tgl": "14/08/2026", "ajp": "XENDIT-001", "detail": "Penarikan saldo Web Raabiha", "debAcc": "1-102", "kreAcc": "1-205", "nominal": "1.000.000" } ] }

Sheet COA
A1: DAFTAR AKUN (CHART OF ACCOUNTS)
A2: Kode akun ini digunakan di seluruh sheet INPUT. Jangan ubah kode akun yang sudah dipakai di jurnal.
A3: kode_akun | B3: nama_akun | C3: kategori | D3: sub_kategori | E3: normal_balance | F3: laporan | G3: saldo_awal | H3: saldo_akhir
A4: 1-101 | B4: Kas Toko (POS) | C4: Aset | D4: Aset Lancar | E4: DB | F4: Neraca | G4: 0 | H4: =IF(E4="DB", G4 + SUMIFS('INPUT Penjualan'!K$4:K$1000, 'INPUT Penjualan'!D$4:D$1000, A4) + SUMIFS('INPUT Pembelian & Produksi'!I$4:I$1000, 'INPUT Pembelian & Produksi'!K$4:K$1000, A4) + SUMIFS('INPUT Beban & Kas Keluar'!F$4:F$1000, 'INPUT Beban & Kas Keluar'!C$4:C$1000, A4) + SUMIFS('INPUT Jurnal Penyesuaian'!H$4:H$500, 'INPUT Jurnal Penyesuaian'!D$4:D$500, A4) - SUMIFS('INPUT Penjualan'!K$4:K$1000, 'INPUT Penjualan'!F$4:F$1000, A4) - SUMIFS('INPUT Pembelian & Produksi'!I$4:I$1000, 'INPUT Pembelian & Produksi'!M$4:M$1000, A4) - SUMIFS('INPUT Beban & Kas Keluar'!F$4:F$1000, 'INPUT Beban & Kas Keluar'!G$4:G$1000, B4) - SUMIFS('INPUT Jurnal Penyesuaian'!H$4:H$500, 'INPUT Jurnal Penyesuaian'!F$4:F$500, A4), G4 + SUMIFS('INPUT Penjualan'!K$4:K$1000, 'INPUT Penjualan'!F$4:F$1000, A4) + SUMIFS('INPUT Pembelian & Produksi'!I$4:I$1000, 'INPUT Pembelian & Produksi'!M$4:M$1000, A4) + SUMIFS('INPUT Jurnal Penyesuaian'!H$4:H$500, 'INPUT Jurnal Penyesuaian'!F$4:F$500, A4) - SUMIFS('INPUT Penjualan'!K$4:K$1000, 'INPUT Penjualan'!D$4:D$1000, A4) - SUMIFS('INPUT Pembelian & Produksi'!I$4:I$1000, 'INPUT Pembelian & Produksi'!K$4:K$1000, A4) - SUMIFS('INPUT Beban & Kas Keluar'!F$4:F$1000, 'INPUT Beban & Kas Keluar'!G$4:G$1000, B4) - SUMIFS('INPUT Jurnal Penyesuaian'!H$4:H$500, 'INPUT Jurnal Penyesuaian'!D$4:D$500, A4)) -> 5000000
A5: 1-102 | B5: Kas Bank BCA CV Sinar Mandani | C5: Aset | D5: Aset Lancar | E5: DB | F5: Neraca | G5: 100000000 | H5: =IF(E5="DB", G5 + SUMIFS('INPUT Penjualan'!K$4:K$1000, 'INPUT Penjualan'!D$4:D$1000, A5) + SUMIFS('INPUT Pembelian & Produksi'!I$4:I$1000, 'INPUT Pembelian & Produksi'!K$4:K$1000, A5) + SUMIFS('INPUT Beban & Kas Keluar'!F$4:F$1000, 'INPUT Beban & Kas Keluar'!C$4:C$1000, A5) + SUMIFS('INPUT Jurnal Penyesuaian'!H$4:H$500, 'INPUT Jurnal Penyesuaian'!D$4:D$500, A5) - SUMIFS('INPUT Penjualan'!K$4:K$1000, 'INPUT Penjualan'!F$4:F$1000, A5) - SUMIFS('INPUT Pembelian & Produksi'!I$4:I$1000, 'INPUT Pembelian & Produksi'!M$4:M$1000, A5) - SUMIFS('INPUT Beban & Kas Keluar'!F$4:F$1000, 'INPUT Beban & Kas Keluar'!G$4:G$1000, B5) - SUMIFS('INPUT Jurnal Penyesuaian'!H$4:H$500, 'INPUT Jurnal Penyesuaian'!F$4:F$500, A5), G5 + SUMIFS('INPUT Penjualan'!K$4:K$1000, 'INPUT Penjualan'!F$4:F$1000, A5) + SUMIFS('INPUT Pembelian & Produksi'!I$4:I$1000, 'INPUT Pembelian & Produksi'!M$4:M$1000, A5) + SUMIFS('INPUT Jurnal Penyesuaian'!H$4:H$500, 'INPUT Jurnal Penyesuaian'!F$4:F$500, A5) - SUMIFS('INPUT Penjualan'!K$4:K$1000, 'INPUT Penjualan'!D$4:D$1000, A5) - SUMIFS('INPUT Pembelian & Produksi'!I$4:I$1000, 'INPUT Pembelian & Produksi'!K$4:K$1000, A5) - SUMIFS('INPUT Beban & Kas Keluar'!F$4:F$1000, 'INPUT Beban & Kas Keluar'!G$4:G$1000, B5) - SUMIFS('INPUT Jurnal Penyesuaian'!H$4:H$500, 'INPUT Jurnal Penyesuaian'!D$4:D$500, A5)) -> 78840000
A6: 1-103 | B6: Kas Bank Mandiri | C6: Aset | D6: Aset Lancar | E6: DB | F6: Neraca | G6: 0 | H6: =IF(E6="DB", G6 + SUMIFS('INPUT Penjualan'!K$4:K$1000, 'INPUT Penjualan'!D$4:D$1000, A6) + SUMIFS('INPUT Pembelian & Produksi'!I$4:I$1000, 'INPUT Pembelian & Produksi'!K$4:K$1000, A6) + SUMIFS('INPUT Beban & Kas Keluar'!F$4:F$1000, 'INPUT Beban & Kas Keluar'!C$4:C$1000, A6) + SUMIFS('INPUT Jurnal Penyesuaian'!H$4:H$500, 'INPUT Jurnal Penyesuaian'!D$4:D$500, A6) - SUMIFS('INPUT Penjualan'!K$4:K$1000, 'INPUT Penjualan'!F$4:F$1000, A6) - SUMIFS('INPUT Pembelian & Produksi'!I$4:I$1000, 'INPUT Pembelian & Produksi'!M$4:M$1000, A6) - SUMIFS('INPUT Beban & Kas Keluar'!F$4:F$1000, 'INPUT Beban & Kas Keluar'!G$4:G$1000, B6) - SUMIFS('INPUT Jurnal Penyesuaian'!H$4:H$500, 'INPUT Jurnal Penyesuaian'!F$4:F$500, A6), G6 + SUMIFS('INPUT Penjualan'!K$4:K$1000, 'INPUT Penjualan'!F$4:F$1000, A6) + SUMIFS('INPUT Pembelian & Produksi'!I$4:I$1000, 'INPUT Pembelian & Produksi'!M$4:M$1000, A6) + SUMIFS('INPUT Jurnal Penyesuaian'!H$4:H$500, 'INPUT Jurnal Penyesuaian'!F$4:F$500, A6) - SUMIFS('INPUT Penjualan'!K$4:K$1000, 'INPUT Penjualan'!D$4:D$1000, A6) - SUMIFS('INPUT Pembelian & Produksi'!I$4:I$1000, 'INPUT Pembelian & Produksi'!K$4:K$1000, A6) - SUMIFS('INPUT Beban & Kas Keluar'!F$4:F$1000, 'INPUT Beban & Kas Keluar'!G$4:G$1000, B6) - SUMIFS('INPUT Jurnal Penyesuaian'!H$4:H$500, 'INPUT Jurnal Penyesuaian'!D$4:D$500, A6)) -> 0
A7: 1-104 | B7: Kas Bank BCA Novianti | C7: Aset | D7: Aset Lancar | E7: DB | F7: Neraca | G7: 0 | H7: =IF(E7="DB", G7 + SUMIFS('INPUT Penjualan'!K$4:K$1000, 'INPUT Penjualan'!D$4:D$1000, A7) + SUMIFS('INPUT Pembelian & Produksi'!I$4:I$1000, 'INPUT Pembelian & Produksi'!K$4:K$1000, A7) + SUMIFS('INPUT Beban & Kas Keluar'!F$4:F$1000, 'INPUT Beban & Kas Keluar'!C$4:C$1000, A7) + SUMIFS('INPUT Jurnal Penyesuaian'!H$4:H$500, 'INPUT Jurnal Penyesuaian'!D$4:D$500, A7) - SUMIFS('INPUT Penjualan'!K$4:K$1000, 'INPUT Penjualan'!F$4:F$1000, A7) - SUMIFS('INPUT Pembelian & Produksi'!I$4:I$1000, 'INPUT Pembelian & Produksi'!M$4:M$1000, A7) - SUMIFS('INPUT Beban & Kas Keluar'!F$4:F$1000, 'INPUT Beban & Kas Keluar'!G$4:G$1000, B7) - SUMIFS('INPUT Jurnal Penyesuaian'!H$4:H$500, 'INPUT Jurnal Penyesuaian'!F$4:F$500, A7), G7 + SUMIFS('INPUT Penjualan'!K$4:K$1000, 'INPUT Penjualan'!F$4:F$1000, A7) + SUMIFS('INPUT Pembelian & Produksi'!I$4:I$1000, 'INPUT Pembelian & Produksi'!M$4:M$1000, A7) + SUMIFS('INPUT Jurnal Penyesuaian'!H$4:H$500, 'INPUT Jurnal Penyesuaian'!F$4:F$500, A7) - SUMIFS('INPUT Penjualan'!K$4:K$1000, 'INPUT Penjualan'!D$4:D$1000, A7) - SUMIFS('INPUT Pembelian & Produksi'!I$4:I$1000, 'INPUT Pembelian & Produksi'!K$4:K$1000, A7) - SUMIFS('INPUT Beban & Kas Keluar'!F$4:F$1000, 'INPUT Beban & Kas Keluar'!G$4:G$1000, B7) - SUMIFS('INPUT Jurnal Penyesuaian'!H$4:H$500, 'INPUT Jurnal Penyesuaian'!D$4:D$500, A7)) -> 2980000
A8: 1-201 | B8: Piutang Shopee | C8: Aset | D8: Piutang Dagang | E8: DB | F8: Neraca | G8: 0 | H8: =IF(E8="DB", G8 + SUMIFS('INPUT Penjualan'!K$4:K$1000, 'INPUT Penjualan'!D$4:D$1000, A8) + SUMIFS('INPUT Pembelian & Produksi'!I$4:I$1000, 'INPUT Pembelian & Produksi'!K$4:K$1000, A8) + SUMIFS('INPUT Beban & Kas Keluar'!F$4:F$1000, 'INPUT Beban & Kas Keluar'!C$4:C$1000, A8) + SUMIFS('INPUT Jurnal Penyesuaian'!H$4:H$500, 'INPUT Jurnal Penyesuaian'!D$4:D$500, A8) - SUMIFS('INPUT Penjualan'!K$4:K$1000, 'INPUT Penjualan'!F$4:F$1000, A8) - SUMIFS('INPUT Pembelian & Produksi'!I$4:I$1000, 'INPUT Pembelian & Produksi'!M$4:M$1000, A8) - SUMIFS('INPUT Beban & Kas Keluar'!F$4:F$1000, 'INPUT Beban & Kas Keluar'!G$4:G$1000, B8) - SUMIFS('INPUT Jurnal Penyesuaian'!H$4:H$500, 'INPUT Jurnal Penyesuaian'!F$4:F$500, A8), G8 + SUMIFS('INPUT Penjualan'!K$4:K$1000, 'INPUT Penjualan'!F$4:F$1000, A8) + SUMIFS('INPUT Pembelian & Produksi'!I$4:I$1000, 'INPUT Pembelian & Produksi'!M$4:M$1000, A8) + SUMIFS('INPUT Jurnal Penyesuaian'!H$4:H$500, 'INPUT Jurnal Penyesuaian'!F$4:F$500, A8) - SUMIFS('INPUT Penjualan'!K$4:K$1000, 'INPUT Penjualan'!D$4:D$1000, A8) - SUMIFS('INPUT Pembelian & Produksi'!I$4:I$1000, 'INPUT Pembelian & Produksi'!K$4:K$1000, A8) - SUMIFS('INPUT Beban & Kas Keluar'!F$4:F$1000, 'INPUT Beban & Kas Keluar'!G$4:G$1000, B8) - SUMIFS('INPUT Jurnal Penyesuaian'!H$4:H$500, 'INPUT Jurnal Penyesuaian'!D$4:D$500, A8)) -> 3500000
A9: 1-202 | B9: Piutang Lazada | C9: Aset | D9: Piutang Dagang | E9: DB | F9: Neraca | G9: 0 | H9: =IF(E9="DB", G9 + SUMIFS('INPUT Penjualan'!K$4:K$1000, 'INPUT Penjualan'!D$4:D$1000, A9) + SUMIFS('INPUT Pembelian & Produksi'!I$4:I$1000, 'INPUT Pembelian & Produksi'!K$4:K$1000, A9) + SUMIFS('INPUT Beban & Kas Keluar'!F$4:F$1000, 'INPUT Beban & Kas Keluar'!C$4:C$1000, A9) + SUMIFS('INPUT Jurnal Penyesuaian'!H$4:H$500, 'INPUT Jurnal Penyesuaian'!D$4:D$500, A9) - SUMIFS('INPUT Penjualan'!K$4:K$1000, 'INPUT Penjualan'!F$4:F$1000, A9) - SUMIFS('INPUT Pembelian & Produksi'!I$4:I$1000, 'INPUT Pembelian & Produksi'!M$4:M$1000, A9) - SUMIFS('INPUT Beban & Kas Keluar'!F$4:F$1000, 'INPUT Beban & Kas Keluar'!G$4:G$1000, B9) - SUMIFS('INPUT Jurnal Penyesuaian'!H$4:H$500, 'INPUT Jurnal Penyesuaian'!F$4:F$500, A9), G9 + SUMIFS('INPUT Penjualan'!K$4:K$1000, 'INPUT Penjualan'!F$4:F$1000, A9) + SUMIFS('INPUT Pembelian & Produksi'!I$4:I$1000, 'INPUT Pembelian & Produksi'!M$4:M$1000, A9) + SUMIFS('INPUT Jurnal Penyesuaian'!H$4:H$500, 'INPUT Jurnal Penyesuaian'!F$4:F$500, A9) - SUMIFS('INPUT Penjualan'!K$4:K$1000, 'INPUT Penjualan'!D$4:D$1000, A9) - SUMIFS('INPUT Pembelian & Produksi'!I$4:I$1000, 'INPUT Pembelian & Produksi'!K$4:K$1000, A9) - SUMIFS('INPUT Beban & Kas Keluar'!F$4:F$1000, 'INPUT Beban & Kas Keluar'!G$4:G$1000, B9) - SUMIFS('INPUT Jurnal Penyesuaian'!H$4:H$500, 'INPUT Jurnal Penyesuaian'!D$4:D$500, A9)) -> 1800000
A10: 1-203 | B10: Piutang Tokopedia | C10: Aset | D10: Piutang Dagang | E10: DB | F10: Neraca | G10: 0 | H10: =IF(E10="DB", G10 + SUMIFS('INPUT Penjualan'!K$4:K$1000, 'INPUT Penjualan'!D$4:D$1000, A10) + SUMIFS('INPUT Pembelian & Produksi'!I$4:I$1000, 'INPUT Pembelian & Produksi'!K$4:K$1000, A10) + SUMIFS('INPUT Beban & Kas Keluar'!F$4:F$1000, 'INPUT Beban & Kas Keluar'!C$4:C$1000, A10) + SUMIFS('INPUT Jurnal Penyesuaian'!H$4:H$500, 'INPUT Jurnal Penyesuaian'!D$4:D$500, A10) - SUMIFS('INPUT Penjualan'!K$4:K$1000, 'INPUT Penjualan'!F$4:F$1000, A10) - SUMIFS('INPUT Pembelian & Produksi'!I$4:I$1000, 'INPUT Pembelian & Produksi'!M$4:M$1000, A10) - SUMIFS('INPUT Beban & Kas Keluar'!F$4:F$1000, 'INPUT Beban & Kas Keluar'!G$4:G$1000, B10) - SUMIFS('INPUT Jurnal Penyesuaian'!H$4:H$500, 'INPUT Jurnal Penyesuaian'!F$4:F$500, A10), G10 + SUMIFS('INPUT Penjualan'!K$4:K$1000, 'INPUT Penjualan'!F$4:F$1000, A10) + SUMIFS('INPUT Pembelian & Produksi'!I$4:I$1000, 'INPUT Pembelian & Produksi'!M$4:M$1000, A10) + SUMIFS('INPUT Jurnal Penyesuaian'!H$4:H$500, 'INPUT Jurnal Penyesuaian'!F$4:F$500, A10) - SUMIFS('INPUT Penjualan'!K$4:K$1000, 'INPUT Penjualan'!D$4:D$1000, A10) - SUMIFS('INPUT Pembelian & Produksi'!I$4:I$1000, 'INPUT Pembelian & Produksi'!K$4:K$1000, A10) - SUMIFS('INPUT Beban & Kas Keluar'!F$4:F$1000, 'INPUT Beban & Kas Keluar'!G$4:G$1000, B10) - SUMIFS('INPUT Jurnal Penyesuaian'!H$4:H$500, 'INPUT Jurnal Penyesuaian'!D$4:D$500, A10)) -> 3600000
A11: 1-204 | B11: Piutang TikTok Shop | C11: Aset | D11: Piutang Dagang | E11: DB | F11: Neraca | G11: 0 | H11: =IF(E11="DB", G11 + SUMIFS('INPUT Penjualan'!K$4:K$1000, 'INPUT Penjualan'!D$4:D$1000, A11) + SUMIFS('INPUT Pembelian & Produksi'!I$4:I$1000, 'INPUT Pembelian & Produksi'!K$4:K$1000, A11) + SUMIFS('INPUT Beban & Kas Keluar'!F$4:F$1000, 'INPUT Beban & Kas Keluar'!C$4:C$1000, A11) + SUMIFS('INPUT Jurnal Penyesuaian'!H$4:H$500, 'INPUT Jurnal Penyesuaian'!D$4:D$500, A11) - SUMIFS('INPUT Penjualan'!K$4:K$1000, 'INPUT Penjualan'!F$4:F$1000, A11) - SUMIFS('INPUT Pembelian & Produksi'!I$4:I$1000, 'INPUT Pembelian & Produksi'!M$4:M$1000, A11) - SUMIFS('INPUT Beban & Kas Keluar'!F$4:F$1000, 'INPUT Beban & Kas Keluar'!G$4:G$1000, B11) - SUMIFS('INPUT Jurnal Penyesuaian'!H$4:H$500, 'INPUT Jurnal Penyesuaian'!F$4:F$500, A11), G11 + SUMIFS('INPUT Penjualan'!K$4:K$1000, 'INPUT Penjualan'!F$4:F$1000, A11) + SUMIFS('INPUT Pembelian & Produksi'!I$4:I$1000, 'INPUT Pembelian & Produksi'!M$4:M$1000, A11) + SUMIFS('INPUT Jurnal Penyesuaian'!H$4:H$500, 'INPUT Jurnal Penyesuaian'!F$4:F$500, A11) - SUMIFS('INPUT Penjualan'!K$4:K$1000, 'INPUT Penjualan'!D$4:D$1000, A11) - SUMIFS('INPUT Pembelian & Produksi'!I$4:I$1000, 'INPUT Pembelian & Produksi'!K$4:K$1000, A11) - SUMIFS('INPUT Beban & Kas Keluar'!F$4:F$1000, 'INPUT Beban & Kas Keluar'!G$4:G$1000, B11) - SUMIFS('INPUT Jurnal Penyesuaian'!H$4:H$500, 'INPUT Jurnal Penyesuaian'!D$4:D$500, A11)) -> 6800000
A12: 1-205 | B12: Piutang Web Raabiha | C12: Aset | D12: Piutang Dagang | E12: DB | F12: Neraca | G12: 0 | H12: =IF(E12="DB", G12 + SUMIFS('INPUT Penjualan'!K$4:K$1000, 'INPUT Penjualan'!D$4:D$1000, A12) + SUMIFS('INPUT Pembelian & Produksi'!I$4:I$1000, 'INPUT Pembelian & Produksi'!K$4:K$1000, A12) + SUMIFS('INPUT Beban & Kas Keluar'!F$4:F$1000, 'INPUT Beban & Kas Keluar'!C$4:C$1000, A12) + SUMIFS('INPUT Jurnal Penyesuaian'!H$4:H$500, 'INPUT Jurnal Penyesuaian'!D$4:D$500, A12) - SUMIFS('INPUT Penjualan'!K$4:K$1000, 'INPUT Penjualan'!F$4:F$1000, A12) - SUMIFS('INPUT Pembelian & Produksi'!I$4:I$1000, 'INPUT Pembelian & Produksi'!M$4:M$1000, A12) - SUMIFS('INPUT Beban & Kas Keluar'!F$4:F$1000, 'INPUT Beban & Kas Keluar'!G$4:G$1000, B12) - SUMIFS('INPUT Jurnal Penyesuaian'!H$4:H$500, 'INPUT Jurnal Penyesuaian'!F$4:F$500, A12), G12 + SUMIFS('INPUT Penjualan'!K$4:K$1000, 'INPUT Penjualan'!F$4:F$1000, A12) + SUMIFS('INPUT Pembelian & Produksi'!I$4:I$1000, 'INPUT Pembelian & Produksi'!M$4:M$1000, A12) + SUMIFS('INPUT Jurnal Penyesuaian'!H$4:H$500, 'INPUT Jurnal Penyesuaian'!F$4:F$500, A12) - SUMIFS('INPUT Penjualan'!K$4:K$1000, 'INPUT Penjualan'!D$4:D$1000, A12) - SUMIFS('INPUT Pembelian & Produksi'!I$4:I$1000, 'INPUT Pembelian & Produksi'!K$4:K$1000, A12) - SUMIFS('INPUT Beban & Kas Keluar'!F$4:F$1000, 'INPUT Beban & Kas Keluar'!G$4:G$1000, B12) - SUMIFS('INPUT Jurnal Penyesuaian'!H$4:H$500, 'INPUT Jurnal Penyesuaian'!D$4:D$500, A12)) -> 0
A13: 1-206 | B13: Piutang Pelanggan Lainnya | C13: Aset | D13: Piutang Dagang | E13: DB | F13: Neraca | G13: 0 | H13: =IF(E13="DB", G13 + SUMIFS('INPUT Penjualan'!K$4:K$1000, 'INPUT Penjualan'!D$4:D$1000, A13) + SUMIFS('INPUT Pembelian & Produksi'!I$4:I$1000, 'INPUT Pembelian & Produksi'!K$4:K$1000, A13) + SUMIFS('INPUT Beban & Kas Keluar'!F$4:F$1000, 'INPUT Beban & Kas Keluar'!C$4:C$1000, A13) + SUMIFS('INPUT Jurnal Penyesuaian'!H$4:H$500, 'INPUT Jurnal Penyesuaian'!D$4:D$500, A13) - SUMIFS('INPUT Penjualan'!K$4:K$1000, 'INPUT Penjualan'!F$4:F$1000, A13) - SUMIFS('INPUT Pembelian & Produksi'!I$4:I$1000, 'INPUT Pembelian & Produksi'!M$4:M$1000, A13) - SUMIFS('INPUT Beban & Kas Keluar'!F$4:F$1000, 'INPUT Beban & Kas Keluar'!G$4:G$1000, B13) - SUMIFS('INPUT Jurnal Penyesuaian'!H$4:H$500, 'INPUT Jurnal Penyesuaian'!F$4:F$500, A13), G13 + SUMIFS('INPUT Penjualan'!K$4:K$1000, 'INPUT Penjualan'!F$4:F$1000, A13) + SUMIFS('INPUT Pembelian & Produksi'!I$4:I$1000, 'INPUT Pembelian & Produksi'!M$4:M$1000, A13) + SUMIFS('INPUT Jurnal Penyesuaian'!H$4:H$500, 'INPUT Jurnal Penyesuaian'!F$4:F$500, A13) - SUMIFS('INPUT Penjualan'!K$4:K$1000, 'INPUT Penjualan'!D$4:D$1000, A13) - SUMIFS('INPUT Pembelian & Produksi'!I$4:I$1000, 'INPUT Pembelian & Produksi'!K$4:K$1000, A13) - SUMIFS('INPUT Beban & Kas Keluar'!F$4:F$1000, 'INPUT Beban & Kas Keluar'!G$4:G$1000, B13) - SUMIFS('INPUT Jurnal Penyesuaian'!H$4:H$500, 'INPUT Jurnal Penyesuaian'!D$4:D$500, A13)) -> 0
A14: 1-301 | B14: Persediaan Bahan Baku | C14: Aset | D14: Persediaan | E14: DB | F14: Neraca | G14: 20000000 | H14: =IF(E14="DB", G14 + SUMIFS('INPUT Penjualan'!K$4:K$1000, 'INPUT Penjualan'!D$4:D$1000, A14) + SUMIFS('INPUT Pembelian & Produksi'!I$4:I$1000, 'INPUT Pembelian & Produksi'!K$4:K$1000, A14) + SUMIFS('INPUT Beban & Kas Keluar'!F$4:F$1000, 'INPUT Beban & Kas Keluar'!C$4:C$1000, A14) + SUMIFS('INPUT Jurnal Penyesuaian'!H$4:H$500, 'INPUT Jurnal Penyesuaian'!D$4:D$500, A14) - SUMIFS('INPUT Penjualan'!K$4:K$1000, 'INPUT Penjualan'!F$4:F$1000, A14) - SUMIFS('INPUT Pembelian & Produksi'!I$4:I$1000, 'INPUT Pembelian & Produksi'!M$4:M$1000, A14) - SUMIFS('INPUT Beban & Kas Keluar'!F$4:F$1000, 'INPUT Beban & Kas Keluar'!G$4:G$1000, B14) - SUMIFS('INPUT Jurnal Penyesuaian'!H$4:H$500, 'INPUT Jurnal Penyesuaian'!F$4:F$500, A14), G14 + SUMIFS('INPUT Penjualan'!K$4:K$1000, 'INPUT Penjualan'!F$4:F$1000, A14) + SUMIFS('INPUT Pembelian & Produksi'!I$4:I$1000, 'INPUT Pembelian & Produksi'!M$4:M$1000, A14) + SUMIFS('INPUT Jurnal Penyesuaian'!H$4:H$500, 'INPUT Jurnal Penyesuaian'!F$4:F$500, A14) - SUMIFS('INPUT Penjualan'!K$4:K$1000, 'INPUT Penjualan'!D$4:D$1000, A14) - SUMIFS('INPUT Pembelian & Produksi'!I$4:I$1000, 'INPUT Pembelian & Produksi'!K$4:K$1000, A14) - SUMIFS('INPUT Beban & Kas Keluar'!F$4:F$1000, 'INPUT Beban & Kas Keluar'!G$4:G$1000, B14) - SUMIFS('INPUT Jurnal Penyesuaian'!H$4:H$500, 'INPUT Jurnal Penyesuaian'!D$4:D$500, A14)) -> 20000000
A15: 1-302 | B15: Persediaan Barang Dalam Proses | C15: Aset | D15: Persediaan | E15: DB | F15: Neraca | G15: 0 | H15: =IF(E15="DB", G15 + SUMIFS('INPUT Penjualan'!K$4:K$1000, 'INPUT Penjualan'!D$4:D$1000, A15) + SUMIFS('INPUT Pembelian & Produksi'!I$4:I$1000, 'INPUT Pembelian & Produksi'!K$4:K$1000, A15) + SUMIFS('INPUT Beban & Kas Keluar'!F$4:F$1000, 'INPUT Beban & Kas Keluar'!C$4:C$1000, A15) + SUMIFS('INPUT Jurnal Penyesuaian'!H$4:H$500, 'INPUT Jurnal Penyesuaian'!D$4:D$500, A15) - SUMIFS('INPUT Penjualan'!K$4:K$1000, 'INPUT Penjualan'!F$4:F$1000, A15) - SUMIFS('INPUT Pembelian & Produksi'!I$4:I$1000, 'INPUT Pembelian & Produksi'!M$4:M$1000, A15) - SUMIFS('INPUT Beban & Kas Keluar'!F$4:F$1000, 'INPUT Beban & Kas Keluar'!G$4:G$1000, B15) - SUMIFS('INPUT Jurnal Penyesuaian'!H$4:H$500, 'INPUT Jurnal Penyesuaian'!F$4:F$500, A15), G15 + SUMIFS('INPUT Penjualan'!K$4:K$1000, 'INPUT Penjualan'!F$4:F$1000, A15) + SUMIFS('INPUT Pembelian & Produksi'!I$4:I$1000, 'INPUT Pembelian & Produksi'!M$4:M$1000, A15) + SUMIFS('INPUT Jurnal Penyesuaian'!H$4:H$500, 'INPUT Jurnal Penyesuaian'!F$4:F$500, A15) - SUMIFS('INPUT Penjualan'!K$4:K$1000, 'INPUT Penjualan'!D$4:D$1000, A15) - SUMIFS('INPUT Pembelian & Produksi'!I$4:I$1000, 'INPUT Pembelian & Produksi'!K$4:K$1000, A15) - SUMIFS('INPUT Beban & Kas Keluar'!F$4:F$1000, 'INPUT Beban & Kas Keluar'!G$4:G$1000, B15) - SUMIFS('INPUT Jurnal Penyesuaian'!H$4:H$500, 'INPUT Jurnal Penyesuaian'!D$4:D$500, A15)) -> 0
... A50: 6-110 | B50: Beban IT, Server & Operational Web | C50: Beban | D50: Operasional | E50: DB | F50: Laba Rugi | G50: 0 | H50: =IF(E50="DB", G50 + SUMIFS('INPUT Penjualan'!K$4:K$1000, 'INPUT Penjualan'!D$4:D$1000, A50) + SUMIFS('INPUT Pembelian & Produksi'!I$4:I$1000, 'INPUT Pembelian & Produksi'!K$4:K$1000, A50) + SUMIFS('INPUT Beban & Kas Keluar'!F$4:F$1000, 'INPUT Beban & Kas Keluar'!C$4:C$1000, A50) + SUMIFS('INPUT Jurnal Penyesuaian'!H$4:H$500, 'INPUT Jurnal Penyesuaian'!D$4:D$500, A50) - SUMIFS('INPUT Penjualan'!K$4:K$1000, 'INPUT Penjualan'!F$4:F$1000, A50) - SUMIFS('INPUT Pembelian & Produksi'!I$4:I$1000, 'INPUT Pembelian & Produksi'!M$4:M$1000, A50) - SUMIFS('INPUT Beban & Kas Keluar'!F$4:F$1000, 'INPUT Beban & Kas Keluar'!G$4:G$1000, B50) - SUMIFS('INPUT Jurnal Penyesuaian'!H$4:H$500, 'INPUT Jurnal Penyesuaian'!F$4:F$500, A50), G50 + SUMIFS('INPUT Penjualan'!K$4:K$1000, 'INPUT Penjualan'!F$4:F$1000, A50) + SUMIFS('INPUT Pembelian & Produksi'!I$4:I$1000, 'INPUT Pembelian & Produksi'!M$4:M$1000, A50) + SUMIFS('INPUT Jurnal Penyesuaian'!H$4:H$500, 'INPUT Jurnal Penyesuaian'!F$4:F$500, A50) - SUMIFS('INPUT Penjualan'!K$4:K$1000, 'INPUT Penjualan'!D$4:D$1000, A50) - SUMIFS('INPUT Pembelian & Produksi'!I$4:I$1000, 'INPUT Pembelian & Produksi'!K$4:K$1000, A50) - SUMIFS('INPUT Beban & Kas Keluar'!F$4:F$1000, 'INPUT Beban & Kas Keluar'!G$4:G$1000, B50) - SUMIFS('INPUT Jurnal Penyesuaian'!H$4:H$500, 'INPUT Jurnal Penyesuaian'!D$4:D$500, A50)) -> 500000

Sheet INPUT Penjualan
A1: INPUT — JURNAL PENJUALAN
A2: POS Toko & Web Raabiha: akan otomatis terisi dari sistem web. Marketplace (Shopee/Lazada/Tokopedia/TikTok): isi manual per rekap settlement dari dashboard marketplace. 1 baris = 1 transaksi atau 1 rekap harian per channel.
A3: tanggal | B3: no_referensi | C3: channel | D3: kode_akun_kas | E3: nama_akun_kas | F3: kode_akun_penjualan | G3: nama_akun_penjualan | H3: gross_sales | I3: diskon | J3: biaya_marketplace | K3: net_sales | L3: keterangan
A4: 46235 | B4: POS-01 | C4: POS Toko | D4: 1-101 | E4: =IF(D4="","",IFERROR(VLOOKUP(D4,COA!A:B,2,FALSE),"-")) -> Kas Toko (POS) | F4: 4-101 | G4: =IF(F4="","",IFERROR(VLOOKUP(F4,COA!A:B,2,FALSE),"-")) -> Penjualan — POS Toko | H4: 5000000 | I4: 0 | J4: 0 | K4: =IF(H4="","",H4-I4-J4) -> 5000000 | L4: Tunai
A5: 46235 | B5: POS-02 | C5: POS Toko | D5: 1-102 | E5: =IF(D5="","",IFERROR(VLOOKUP(D5,COA!A:B,2,FALSE),"-")) -> Kas Bank BCA CV Sinar Mandani | F5: 4-101 | G5: =IF(F5="","",IFERROR(VLOOKUP(F5,COA!A:B,2,FALSE),"-")) -> Penjualan — POS Toko | H5: 2000000 | I5: 0 | J5: 10000 | K5: =IF(H5="","",H5-I5-J5) -> 1990000 | L5: Gesek EDC
A6: 46236 | B6: WEB-01 | C6: Web Raabiha | D6: 1-205 | E6: =IF(D6="","",IFERROR(VLOOKUP(D6,COA!A:B,2,FALSE),"-")) -> Piutang Web Raabiha | F6: 4-102 | G6: =IF(F6="","",IFERROR(VLOOKUP(F6,COA!A:B,2,FALSE),"-")) -> Penjualan — Web Raabiha | H6: 3000000 | I6: 0 | J6: 20000 | K6: =IF(H6="","",H6-I6-J6) -> 2980000 | L6: Payment Gateway
A7: 46237 | B7: SPE-01 | C7: Shopee | D7: 1-201 | E7: =IF(D7="","",IFERROR(VLOOKUP(D7,COA!A:B,2,FALSE),"-")) -> Piutang Shopee | F7: 4-103 | G7: =IF(F7="","",IFERROR(VLOOKUP(F7,COA!A:B,2,FALSE),"-")) -> Penjualan — Shopee | H7: 10000000 | I7: 0 | J7: 1500000 | K7: =IF(H7="","",H7-I7-J7) -> 8500000 | L7: Settlement Shopee
A8: 46238 | B8: TTK-01 | C8: TikTok Shop | D8: 1-204 | E8: =IF(D8="","",IFERROR(VLOOKUP(D8,COA!A:B,2,FALSE),"-")) -> Piutang TikTok Shop | F8: 4-106 | G8: =IF(F8="","",IFERROR(VLOOKUP(F8,COA!A:B,2,FALSE),"-")) -> Penjualan — TikTok Shop | H8: 8000000 | I8: 0 | J8: 1200000 | K8: =IF(H8="","",H8-I8-J8) -> 6800000 | L8: Settlement TikTok
A9: 46239 | B9: TKP-01 | C9: Tokopedia | D9: 1-203 | E9: =IF(D9="","",IFERROR(VLOOKUP(D9,COA!A:B,2,FALSE),"-")) -> Piutang Tokopedia | F9: 4-105 | G9: =IF(F9="","",IFERROR(VLOOKUP(F9,COA!A:B,2,FALSE),"-")) -> Penjualan — Tokopedia | H9: 4000000 | I9: 0 | J9: 400000 | K9: =IF(H9="","",H9-I9-J9) -> 3600000 | L9: Settlement Tokopedia
A10: 46240 | B10: LZD-01 | C10: Lazada | D10: 1-202 | E10: =IF(D10="","",IFERROR(VLOOKUP(D10,COA!A:B,2,FALSE),"-")) -> Piutang Lazada | F10: 4-104 | G10: =IF(F10="","",IFERROR(VLOOKUP(F10,COA!A:B,2,FALSE),"-")) -> Penjualan — Lazada | H10: 2000000 | I10: 0 | J10: 200000 | K10: =IF(H10="","",H10-I10-J10) -> 1800000 | L10: Settlement Lazada
E11: =IF(D11="","",IFERROR(VLOOKUP(D11,COA!A:B,2,FALSE),"-")) | G11: =IF(F11="","",IFERROR(VLOOKUP(F11,COA!A:B,2,FALSE),"-")) | K11: =IF(H11="","",H11-I11-J11)
E12: =IF(D12="","",IFERROR(VLOOKUP(D12,COA!A:B,2,FALSE),"-")) | G12: =IF(F12="","",IFERROR(VLOOKUP(F12,COA!A:B,2,FALSE),"-")) | K12: =IF(H12="","",H12-I12-J12)
E13: =IF(D13="","",IFERROR(VLOOKUP(D13,COA!A:B,2,FALSE),"-")) | G13: =IF(F13="","",IFERROR(VLOOKUP(F13,COA!A:B,2,FALSE),"-")) | K13: =IF(H13="","",H13-I13-J13)
E14: =IF(D14="","",IFERROR(VLOOKUP(D14,COA!A:B,2,FALSE),"-")) | G14: =IF(F14="","",IFERROR(VLOOKUP(F14,COA!A:B,2,FALSE),"-")) | K14: =IF(H14="","",H14-I14-J14)
E15: =IF(D15="","",IFERROR(VLOOKUP(D15,COA!A:B,2,FALSE),"-")) | G15: =IF(F15="","",IFERROR(VLOOKUP(F15,COA!A:B,2,FALSE),"-")) | K15: =IF(H15="","",H15-I15-J15)
E16: =IF(D16="","",IFERROR(VLOOKUP(D16,COA!A:B,2,FALSE),"-")) | G16: =IF(F16="","",IFERROR(VLOOKUP(F16,COA!A:B,2,FALSE),"-")) | K16: =IF(H16="","",H16-I16-J16)
E17: =IF(D17="","",IFERROR(VLOOKUP(D17,COA!A:B,2,FALSE),"-")) | G17: =IF(F17="","",IFERROR(VLOOKUP(F17,COA!A:B,2,FALSE),"-")) | K17: =IF(H17="","",H17-I17-J17)
E18: =IF(D18="","",IFERROR(VLOOKUP(D18,COA!A:B,2,FALSE),"-")) | G18: =IF(F18="","",IFERROR(VLOOKUP(F18,COA!A:B,2,FALSE),"-")) | K18: =IF(H18="","",H18-I18-J18)
E19: =IF(D19="","",IFERROR(VLOOKUP(D19,COA!A:B,2,FALSE),"-")) | G19: =IF(F19="","",IFERROR(VLOOKUP(F19,COA!A:B,2,FALSE),"-")) | K19: =IF(H19="","",H19-I19-J19)
E20: =IF(D20="","",IFERROR(VLOOKUP(D20,COA!A:B,2,FALSE),"-")) | G20: =IF(F20="","",IFERROR(VLOOKUP(F20,COA!A:B,2,FALSE),"-")) | K20: =IF(H20="","",H20-I20-J20)
E21: =IF(D21="","",IFERROR(VLOOKUP(D21,COA!A:B,2,FALSE),"-")) | G21: =IF(F21="","",IFERROR(VLOOKUP(F21,COA!A:B,2,FALSE),"-")) | K21: =IF(H21="","",H21-I21-J21)
E22: =IF(D22="","",IFERROR(VLOOKUP(D22,COA!A:B,2,FALSE),"-")) | G22: =IF(F22="","",IFERROR(VLOOKUP(F22,COA!A:B,2,FALSE),"-")) | K22: =IF(H22="","",H22-I22-J22)
... E500: =IF(D500="","",IFERROR(VLOOKUP(D500,COA!A:B,2,FALSE),"-")) | G500: =IF(F500="","",IFERROR(VLOOKUP(F500,COA!A:B,2,FALSE),"-")) | K500: =IF(H500="","",H500-I500-J500)
A502: RINGKASAN PER CHANNEL
A503: POS Toko | H503: =SUMIF(C4:C500,"POS Toko",H4:H500) -> 7000000 | I503: =SUMIF(C4:C500,"POS Toko",I4:I500) -> 0 | J503: =SUMIF(C4:C500,"POS Toko",J4:J500) -> 10000 | K503: =SUMIF(C4:C500,"POS Toko",K4:K500) -> 6990000
A504: Web Raabiha | H504: =SUMIF(C4:C500,"Web Raabiha",H4:H500) -> 3000000 | I504: =SUMIF(C4:C500,"Web Raabiha",I4:I500) -> 0 | J504: =SUMIF(C4:C500,"Web Raabiha",J4:J500) -> 20000 | K504: =SUMIF(C4:C500,"Web Raabiha",K4:K500) -> 2980000
A505: Shopee | H505: =SUMIF(C4:C500,"Shopee",H4:H500) -> 10000000 | I505: =SUMIF(C4:C500,"Shopee",I4:I500) -> 0 | J505: =SUMIF(C4:C500,"Shopee",J4:J500) -> 1500000 | K505: =SUMIF(C4:C500,"Shopee",K4:K500) -> 8500000
A506: Lazada | H506: =SUMIF(C4:C500,"Lazada",H4:H500) -> 2000000 | I506: =SUMIF(C4:C500,"Lazada",I4:I500) -> 0 | J506: =SUMIF(C4:C500,"Lazada",J4:J500) -> 200000 | K506: =SUMIF(C4:C500,"Lazada",K4:K500) -> 1800000
A507: Tokopedia | H507: =SUMIF(C4:C500,"Tokopedia",H4:H500) -> 4000000 | I507: =SUMIF(C4:C500,"Tokopedia",I4:I500) -> 0 | J507: =SUMIF(C4:C500,"Tokopedia",J4:J500) -> 400000 | K507: =SUMIF(C4:C500,"Tokopedia",K4:K500) -> 3600000
A508: TikTok Shop | H508: =SUMIF(C4:C500,"TikTok Shop",H4:H500) -> 8000000 | I508: =SUMIF(C4:C500,"TikTok Shop",I4:I500) -> 0 | J508: =SUMIF(C4:C500,"TikTok Shop",J4:J500) -> 1200000 | K508: =SUMIF(C4:C500,"TikTok Shop",K4:K500) -> 6800000

Sheet INPUT Pembelian & Produksi
A1: INPUT — PEMBELIAN & BIAYA PRODUKSI KONVEKSI
A2: Gunakan untuk: (1) Beli bahan baku konveksi dari supplier; (2) Restok baju jadi dari supplier; (3) Bayar ongkos jahit/potong per batch produksi.
A3: tanggal | B3: no_faktur | C3: jenis | D3: supplier | E3: keterangan_item | F3: qty | G3: satuan | H3: harga_satuan | I3: total | J3: status_bayar | K3: kode_akun_debet | L3: nama_akun_debet | M3: kode_akun_kredit | N3: nama_akun_kredit
A4: 46235 | B4: BB-01 | C4: Bahan Baku | D4: PT. Sunnytex | E4: Kain Ity | F4: 100 | G4: kg | H4: 100000 | I4: =IF(F4="","",F4*H4) -> 10000000 | J4: Tunai | K4: 5-201 | L4: =IF(K4="","",IFERROR(VLOOKUP(K4,COA!A:B,2,FALSE),"-")) -> Biaya Bahan Baku Konveksi | M4: 1-102 | N4: =IF(M4="","",IFERROR(VLOOKUP(M4,COA!A:B,2,FALSE),"-")) -> Kas Bank BCA CV Sinar Mandani
A5: 46237 | B5: BP-01 | C5: Ongkos Jahit | D5: Konveksi | E5: Jahit Baju | F5: 500 | G5: pcs | H5: 10000 | I5: =IF(F5="","",F5*H5) -> 5000000 | J5: Tunai | K5: 5-202 | L5: =IF(K5="","",IFERROR(VLOOKUP(K5,COA!A:B,2,FALSE),"-")) -> Biaya Ongkos Jahit & Potong | M5: 1-102 | N5: =IF(M5="","",IFERROR(VLOOKUP(M5,COA!A:B,2,FALSE),"-")) -> Kas Bank BCA CV Sinar Mandani
A6: 46239 | B6: AK-01 | C6: Aksesoris | D6: Toko Aksesoris | E6: Logo Bross | F6: 1000 | G6: pcs | H6: 1000 | I6: =IF(F6="","",F6*H6) -> 1000000 | J6: Tunai | K6: 5-203 | L6: =IF(K6="","",IFERROR(VLOOKUP(K6,COA!A:B,2,FALSE),"-")) -> Biaya Aksesoris & Packing Produksi | M6: 1-102 | N6: =IF(M6="","",IFERROR(VLOOKUP(M6,COA!A:B,2,FALSE),"-")) -> Kas Bank BCA CV Sinar Mandani
A7: 46242 | B7: PRT-01 | C7: Peralatan | D7: Toko Mebel | E7: Meja Office | F7: 1 | G7: unit | H7: 1000000 | I7: =IF(F7="","",F7*H7) -> 1000000 | J7: Tunai | K7: 1-401 | L7: =IF(K7="","",IFERROR(VLOOKUP(K7,COA!A:B,2,FALSE),"-")) -> Peralatan & Mesin Jahit | M7: 1-102 | N7: =IF(M7="","",IFERROR(VLOOKUP(M7,COA!A:B,2,FALSE),"-")) -> Kas Bank BCA CV Sinar Mandani
I8: =IF(F8="","",F8*H8) | L8: =IF(K8="","",IFERROR(VLOOKUP(K8,COA!A:B,2,FALSE),"-")) | N8: =IF(M8="","",IFERROR(VLOOKUP(M8,COA!A:B,2,FALSE),"-"))
I9: =IF(F9="","",F9*H9) | L9: =IF(K9="","",IFERROR(VLOOKUP(K9,COA!A:B,2,FALSE),"-")) | N9: =IF(M9="","",IFERROR(VLOOKUP(M9,COA!A:B,2,FALSE),"-"))
I10: =IF(F10="","",F10*H10) | L10: =IF(K10="","",IFERROR(VLOOKUP(K10,COA!A:B,2,FALSE),"-")) | N10: =IF(M10="","",IFERROR(VLOOKUP(M10,COA!A:B,2,FALSE),"-"))
I11: =IF(F11="","",F11*H11) | L11: =IF(K11="","",IFERROR(VLOOKUP(K11,COA!A:B,2,FALSE),"-")) | N11: =IF(M11="","",IFERROR(VLOOKUP(M11,COA!A:B,2,FALSE),"-"))
I12: =IF(F12="","",F12*H12) | L12: =IF(K12="","",IFERROR(VLOOKUP(K12,COA!A:B,2,FALSE),"-")) | N12: =IF(M12="","",IFERROR(VLOOKUP(M12,COA!A:B,2,FALSE),"-"))
I13: =IF(F13="","",F13*H13) | L13: =IF(K13="","",IFERROR(VLOOKUP(K13,COA!A:B,2,FALSE),"-")) | N13: =IF(M13="","",IFERROR(VLOOKUP(M13,COA!A:B,2,FALSE),"-"))
I14: =IF(F14="","",F14*H14) | L14: =IF(K14="","",IFERROR(VLOOKUP(K14,COA!A:B,2,FALSE),"-")) | N14: =IF(M14="","",IFERROR(VLOOKUP(M14,COA!A:B,2,FALSE),"-"))
I15: =IF(F15="","",F15*H15) | L15: =IF(K15="","",IFERROR(VLOOKUP(K15,COA!A:B,2,FALSE),"-")) | N15: =IF(M15="","",IFERROR(VLOOKUP(M15,COA!A:B,2,FALSE),"-"))
I16: =IF(F16="","",F16*H16) | L16: =IF(K16="","",IFERROR(VLOOKUP(K16,COA!A:B,2,FALSE),"-")) | N16: =IF(M16="","",IFERROR(VLOOKUP(M16,COA!A:B,2,FALSE),"-"))
I17: =IF(F17="","",F17*H17) | L17: =IF(K17="","",IFERROR(VLOOKUP(K17,COA!A:B,2,FALSE),"-")) | N17: =IF(M17="","",IFERROR(VLOOKUP(M17,COA!A:B,2,FALSE),"-"))
I18: =IF(F18="","",F18*H18) | L18: =IF(K18="","",IFERROR(VLOOKUP(K18,COA!A:B,2,FALSE),"-")) | N18: =IF(M18="","",IFERROR(VLOOKUP(M18,COA!A:B,2,FALSE),"-"))
I19: =IF(F19="","",F19*H19) | L19: =IF(K19="","",IFERROR(VLOOKUP(K19,COA!A:B,2,FALSE),"-")) | N19: =IF(M19="","",IFERROR(VLOOKUP(M19,COA!A:B,2,FALSE),"-"))
... I500: =IF(F500="","",F500*H500) | L500: =IF(K500="","",IFERROR(VLOOKUP(K500,COA!A:B,2,FALSE),"-")) | N500: =IF(M500="","",IFERROR(VLOOKUP(M500,COA!A:B,2,FALSE),"-"))

Sheet INPUT Beban & Kas Keluar
A1: INPUT — BEBAN OPERASIONAL & KAS KELUAR
A2: Catat semua pengeluaran operasional: gaji; sewa; listrik; iklan; kurir; dll. 1 baris = 1 bukti/transaksi. Pilih kode akun dari COA.
A3: tanggal | B3: no_bukti | C3: kode_akun_beban | D3: nama_akun_beban | E3: keterangan_detail | F3: nominal | G3: sumber_kas | H3: keterangan
A4: 46235 | B4: B-01 | C4: 6-101 | D4: =IF(C4="","",IFERROR(VLOOKUP(C4,COA!A:B,2,FALSE),"-")) -> Beban Gaji Karyawan | E4: Gaji Tim Toko | F4: 5000000 | G4: Kas Bank BCA CV Sinar Mandani
A5: 46235 | B5: B-02 | C5: 6-102 | D5: =IF(C5="","",IFERROR(VLOOKUP(C5,COA!A:B,2,FALSE),"-")) -> Beban Sewa Tempat | E5: Sewa Ruko | F5: 2000000 | G5: Kas Bank BCA CV Sinar Mandani
A6: 46236 | B6: B-03 | C6: 6-103 | D6: =IF(C6="","",IFERROR(VLOOKUP(C6,COA!A:B,2,FALSE),"-")) -> Beban Listrik; Air & Internet | E6: Listrik & Biznet | F6: 500000 | G6: Kas Bank BCA CV Sinar Mandani
A7: 46237 | B7: B-04 | C7: 6-104 | D7: =IF(C7="","",IFERROR(VLOOKUP(C7,COA!A:B,2,FALSE),"-")) -> Beban Pemasaran & Iklan Digital | E7: TikTok Ads | F7: 1000000 | G7: Kas Bank BCA CV Sinar Mandani
A8: 46238 | B8: B-05 | C8: 6-105 | D8: =IF(C8="","",IFERROR(VLOOKUP(C8,COA!A:B,2,FALSE),"-")) -> Beban Ongkos Kirim / Kurir | E8: Selisih Nombok Ongkir | F8: 100000 | G8: Kas Bank BCA CV Sinar Mandani
A9: 46239 | B9: B-06 | C9: 6-107 | D9: =IF(C9="","",IFERROR(VLOOKUP(C9,COA!A:B,2,FALSE),"-")) -> Beban Administrasi & Bank | E9: Biaya Transfer | F9: 50000 | G9: Kas Bank BCA CV Sinar Mandani
A10: 46240 | B10: B-07 | C10: 6-110 | D10: =IF(C10="","",IFERROR(VLOOKUP(C10,COA!A:B,2,FALSE),"-")) -> Beban IT, Server & Operational Web | E10: Vercel, Biteship, Resend | F10: 500000 | G10: Kas Bank BCA CV Sinar Mandani
A11: 46241 | B11: B-08 | C11: 3-102 | D11: =IF(C11="","",IFERROR(VLOOKUP(C11,COA!A:B,2,FALSE),"-")) -> Prive Pemilik | E11: Ambil Uang Pribadi | F11: 2000000 | G11: Kas Bank BCA CV Sinar Mandani
D12: =IF(C12="","",IFERROR(VLOOKUP(C12,COA!A:B,2,FALSE),"-"))
D13: =IF(C13="","",IFERROR(VLOOKUP(C13,COA!A:B,2,FALSE),"-"))
D14: =IF(C14="","",IFERROR(VLOOKUP(C14,COA!A:B,2,FALSE),"-"))
D15: =IF(C15="","",IFERROR(VLOOKUP(C15,COA!A:B,2,FALSE),"-"))
D16: =IF(C16="","",IFERROR(VLOOKUP(C16,COA!A:B,2,FALSE),"-"))
D17: =IF(C17="","",IFERROR(VLOOKUP(C17,COA!A:B,2,FALSE),"-"))
D18: =IF(C18="","",IFERROR(VLOOKUP(C18,COA!A:B,2,FALSE),"-"))
D19: =IF(C19="","",IFERROR(VLOOKUP(C19,COA!A:B,2,FALSE),"-"))
D20: =IF(C20="","",IFERROR(VLOOKUP(C20,COA!A:B,2,FALSE),"-"))
D21: =IF(C21="","",IFERROR(VLOOKUP(C21,COA!A:B,2,FALSE),"-"))
D22: =IF(C22="","",IFERROR(VLOOKUP(C22,COA!A:B,2,FALSE),"-"))
D23: =IF(C23="","",IFERROR(VLOOKUP(C23,COA!A:B,2,FALSE),"-"))
... D497: =IF(C497="","",IFERROR(VLOOKUP(C497,COA!A:B,2,FALSE),"-"))
A500: RINGKASAN TOTAL BEBAN PER AKUN (OTOMATIS)
A501: 6-101 | B501: Beban Gaji | F501: =SUMIF(C4:C497,"6-101",F4:F497) -> 5000000
A502: 6-102 | B502: Beban Sewa | F502: =SUMIF(C4:C497,"6-102",F4:F497) -> 2000000
A503: 6-103 | B503: Beban Listrik | F503: =SUMIF(C4:C497,"6-103",F4:F497) -> 500000
A504: 6-104 | B504: Beban Pemasaran | F504: =SUMIF(C4:C497,"6-104",F4:F497) -> 1000000
A505: 6-105 | B505: Beban Kurir | F505: =SUMIF(C4:C497,"6-105",F4:F497) -> 100000
A506: 6-106 | B506: Beban Penyusutan | F506: =SUMIF(C4:C497,"6-106",F4:F497) -> 0
A507: 6-107 | B507: Beban Admin & Bank | F507: =SUMIF(C4:C497,"6-107",F4:F497) -> 50000
A508: 6-108 | B508: Beban Perlengkapan | F508: =SUMIF(C4:C497,"6-108",F4:F497) -> 0
A509: 6-109 | B509: Beban Lain-lain | F509: =SUMIF(C4:C497,"6-109",F4:F497) -> 0
A510: TOTAL SEMUA BEBAN | F510: =SUM(F501:F509) -> 8650000

Sheet INPUT Jurnal Penyesuaian
A1: INPUT — JURNAL PENYESUAIAN (AKHIR PERIODE)
A2: Diisi akhir bulan/tahun untuk: penyusutan aset; stok opname (selisih persediaan); biaya dibayar dimuka; reklasifikasi; dan koreksi jurnal.
A3: tanggal | B3: no_ajp | C3: keterangan_penyesuaian | D3: kode_akun_debet | E3: nama_akun_debet | F3: kode_akun_kredit | G3: nama_akun_kredit | H3: nominal
A4: 46242 | B4: AJP-WEB | C4: Penarikan Web ke Bank Owner | D4: 1-104 | E4: =IF(D4="","",IFERROR(VLOOKUP(D4,COA!A:B,2,FALSE),"-")) -> Kas Bank BCA Novianti | F4: 1-205 | G4: =IF(F4="","",IFERROR(VLOOKUP(F4,COA!A:B,2,FALSE),"-")) -> Piutang Web Raabiha | H4: 2980000
A5: 46243 | B5: AJP-SPE | C5: Penarikan Shopee ke Bank Toko | D5: 1-102 | E5: =IF(D5="","",IFERROR(VLOOKUP(D5,COA!A:B,2,FALSE),"-")) -> Kas Bank BCA CV Sinar Mandani | F5: 1-201 | G5: =IF(F5="","",IFERROR(VLOOKUP(F5,COA!A:B,2,FALSE),"-")) -> Piutang Shopee | H5: 5000000
A6: 46244 | B6: AJP-PENY | C6: Penyusutan Peralatan Bulan Ini | D6: 6-106 | E6: =IF(D6="","",IFERROR(VLOOKUP(D6,COA!A:B,2,FALSE),"-")) -> Beban Penyusutan Aset | F6: 1-402 | G6: =IF(F6="","",IFERROR(VLOOKUP(F6,COA!A:B,2,FALSE),"-")) -> Akumulasi Penyusutan Peralatan | H6: 200000
E7: =IF(D7="","",IFERROR(VLOOKUP(D7,COA!A:B,2,FALSE),"-")) | G7: =IF(F7="","",IFERROR(VLOOKUP(F7,COA!A:B,2,FALSE),"-"))
E8: =IF(D8="","",IFERROR(VLOOKUP(D8,COA!A:B,2,FALSE),"-")) | G8: =IF(F8="","",IFERROR(VLOOKUP(F8,COA!A:B,2,FALSE),"-"))
E9: =IF(D9="","",IFERROR(VLOOKUP(D9,COA!A:B,2,FALSE),"-")) | G9: =IF(F9="","",IFERROR(VLOOKUP(F9,COA!A:B,2,FALSE),"-"))
E10: =IF(D10="","",IFERROR(VLOOKUP(D10,COA!A:B,2,FALSE),"-")) | G10: =IF(F10="","",IFERROR(VLOOKUP(F10,COA!A:B,2,FALSE),"-"))
E11: =IF(D11="","",IFERROR(VLOOKUP(D11,COA!A:B,2,FALSE),"-")) | G11: =IF(F11="","",IFERROR(VLOOKUP(F11,COA!A:B,2,FALSE),"-"))
E12: =IF(D12="","",IFERROR(VLOOKUP(D12,COA!A:B,2,FALSE),"-")) | G12: =IF(F12="","",IFERROR(VLOOKUP(F12,COA!A:B,2,FALSE),"-"))
E13: =IF(D13="","",IFERROR(VLOOKUP(D13,COA!A:B,2,FALSE),"-")) | G13: =IF(F13="","",IFERROR(VLOOKUP(F13,COA!A:B,2,FALSE),"-"))
E14: =IF(D14="","",IFERROR(VLOOKUP(D14,COA!A:B,2,FALSE),"-")) | G14: =IF(F14="","",IFERROR(VLOOKUP(F14,COA!A:B,2,FALSE),"-"))
E15: =IF(D15="","",IFERROR(VLOOKUP(D15,COA!A:B,2,FALSE),"-")) | G15: =IF(F15="","",IFERROR(VLOOKUP(F15,COA!A:B,2,FALSE),"-"))
E16: =IF(D16="","",IFERROR(VLOOKUP(D16,COA!A:B,2,FALSE),"-")) | G16: =IF(F16="","",IFERROR(VLOOKUP(F16,COA!A:B,2,FALSE),"-"))
E17: =IF(D17="","",IFERROR(VLOOKUP(D17,COA!A:B,2,FALSE),"-")) | G17: =IF(F17="","",IFERROR(VLOOKUP(F17,COA!A:B,2,FALSE),"-"))
E18: =IF(D18="","",IFERROR(VLOOKUP(D18,COA!A:B,2,FALSE),"-")) | G18: =IF(F18="","",IFERROR(VLOOKUP(F18,COA!A:B,2,FALSE),"-"))
... E499: =IF(D499="","",IFERROR(VLOOKUP(D499,COA!A:B,2,FALSE),"-")) | G499: =IF(F499="","",IFERROR(VLOOKUP(F499,COA!A:B,2,FALSE),"-"))

Sheet Buku Besar
A1: BUKU BESAR (GENERAL LEDGER)
A2: Pilih kode akun di sel B3 untuk melihat mutasi akun tersebut.
A3: PILIH KODE AKUN: | B3: 6-103 | C3: Nama Akun: | D3: =IFERROR(VLOOKUP(B3,COA!A:B,2,FALSE),"Kode tidak ditemukan") -> Beban Listrik; Air & Internet | F3: Tgl Mulai (Opsional): | G3: 46053 | H3: 46387
